Workbook

Sheet 🌿 Herb Lookup
A2: 🌿 The Greenman Magical Herb Oracle 🌿
A4: 🌿 Select Herb: | C4: LEMONGRASS
A6: 🌿 IDENTITY
A7: =IFERROR("🌿 "&VLOOKUP($C$4,_d_herbs!$A:$BL,2,0),"")
A8: =IFERROR("( "&VLOOKUP($C$4,_d_herbs!$A:$BL,1,0)&" )","")
A9: =IFERROR("✦ "&VLOOKUP($C$4,_d_herbs!$A:$BL,3,0),"")
A11: 🔮 MAGICAL USES
B12: MAGICAL USES | C12: =IFERROR(VLOOKUP($C$4,_d_herbs!$A:$BL,4,0),"")
A14: 💫 SPIRITUAL & POWERS
B15: POWERS | C15: =IFERROR(VLOOKUP($C$4,_d_herbs!$A:$BL,13,0),"")
B16: SPIRITUAL USES | C16: =IFERROR(VLOOKUP($C$4,_d_herbs!$A:$BL,14,0),"")
A18: 📖 CORRESPONDENCES
B19: ASSOCIATION | C19: =IFERROR(VLOOKUP($C$4,_d_herbs!$A:$BL,5,0),"")
B20: ELEMENT | C20: =IFERROR(VLOOKUP($C$4,_d_herbs!$A:$BL,7,0),"")
B21: ENERGY | C21: =IFERROR(VLOOKUP($C$4,_d_herbs!$A:$BL,8,0),"")
B22: DAY | C22: =IFERROR(VLOOKUP($C$4,_d_herbs!$A:$BL,9,0),"")
B23: DEITY | C23: =IFERROR(VLOOKUP($C$4,_d_herbs!$A:$BL,10,0),"")
B24: SABBAT | C24: =IFERROR(VLOOKUP($C$4,_d_herbs!$A:$BL,11,0),"")
B25: PLANET | C25: =IFERROR(VLOOKUP($C$4,_d_herbs!$A:$BL,6,0),"")
B26: ZODIAC SIGN | C26: =IFERROR(VLOOKUP($C$4,_d_herbs!$A:$BL,63,0),"")
A28: ◈ ASSOCIATED CRYSTALS
B29: CRYSTAL 1 | C29: =IFERROR(VLOOKUP($C$4,_d_herbs!$A:$BL,39,0),"")
B30: USES | C30: =IFERROR(VLOOKUP($C$4,_d_herbs!$A:$BL,40,0),"")
B31: POWERS | C31: =IFERROR(VLOOKUP($C$4,_d_herbs!$A:$BL,41,0),"")
B33: CRYSTAL 2 | C33: =IFERROR(VLOOKUP($C$4,_d_herbs!$A:$BL,42,0),"")
B34: USES | C34: =IFERROR(VLOOKUP($C$4,_d_herbs!$A:$BL,43,0),"")
B35: POWERS | C35: =IFERROR(VLOOKUP($C$4,_d_herbs!$A:$BL,44,0),"")
B37: CRYSTAL 3 | C37: =IFERROR(VLOOKUP($C$4,_d_herbs!$A:$BL,45,0),"")
B38: USES | C38: =IFERROR(VLOOKUP($C$4,_d_herbs!$A:$BL,46,0),"")
B39: POWERS | C39: =IFERROR(VLOOKUP($C$4,_d_herbs!$A:$BL,47,0),"")
B41: CRYSTAL 4 | C41: =IFERROR(VLOOKUP($C$4,_d_herbs!$A:$BL,48,0),"")
B42: USES | C42: =IFERROR(VLOOKUP($C$4,_d_herbs!$A:$BL,49,0),"")
B43: POWERS | C43: =IFERROR(VLOOKUP($C$4,_d_herbs!$A:$BL,50,0),"")
A46: 🫙 ASSOCIATED OILS
B47: OIL 1 | C47: =IFERROR(VLOOKUP($C$4,_d_herbs!$A:$BL,51,0),"")
B48: USES | C48: =IFERROR(VLOOKUP($C$4,_d_herbs!$A:$BL,52,0),"")
B49: SPIRITUAL | C49: =IFERROR(VLOOKUP($C$4,_d_herbs!$A:$BL,53,0),"")
B51: OIL 2 | C51: =IFERROR(VLOOKUP($C$4,_d_herbs!$A:$BL,55,0),"")
B52: USES | C52: =IFERROR(VLOOKUP($C$4,_d_herbs!$A:$BL,56,0),"")
B53: SPIRITUAL | C53: =IFERROR(VLOOKUP($C$4,_d_herbs!$A:$BL,57,0),"")
...

Sheet ◈ Crystal Lookup
A2: ◈ The Greenman Crystal Oracle ◈
A4: ◈ Select Crystal: | C4: Apache Tears
A6: ◈ IDENTITY
A7: =IFERROR("◈ "&VLOOKUP($C$4,_d_crystals!$A:$AZ,1,0),"")
A8: =IFERROR("( "&VLOOKUP($C$4,_d_crystals!$A:$AZ,2,0)&" )","")
A9: =IFERROR("✦ "&VLOOKUP($C$4,_d_crystals!$A:$AZ,3,0),"")
A11: 🔮 MAGICAL USES
B12: MAGICAL USES | C12: =IFERROR(VLOOKUP($C$4,_d_crystals!$A:$AZ,4,0),"")
A14: 💫 SPIRITUAL & POWERS
B15: POWERS | C15: =IFERROR(VLOOKUP($C$4,_d_crystals!$A:$AZ,13,0),"")
B16: SPIRITUAL USES | C16: =IFERROR(VLOOKUP($C$4,_d_crystals!$A:$AZ,14,0),"")
A18: 📖 CORRESPONDENCES
B19: ASSOCIATION | C19: =IFERROR(VLOOKUP($C$4,_d_crystals!$A:$AZ,5,0),"")
B20: ELEMENT | C20: =IFERROR(VLOOKUP($C$4,_d_crystals!$A:$AZ,7,0),"")
B21: ENERGY | C21: =IFERROR(VLOOKUP($C$4,_d_crystals!$A:$AZ,8,0),"")
B22: DAY | C22: =IFERROR(VLOOKUP($C$4,_d_crystals!$A:$AZ,9,0),"")
B23: DEITY | C23: =IFERROR(VLOOKUP($C$4,_d_crystals!$A:$AZ,10,0),"")
B24: SABBAT | C24: =IFERROR(VLOOKUP($C$4,_d_crystals!$A:$AZ,11,0),"")
B25: PLANET | C25: =IFERROR(VLOOKUP($C$4,_d_crystals!$A:$AZ,6,0),"")
A27: 🌿 ASSOCIATED HERBS
B28: HERB 1 | C28: =IFERROR(VLOOKUP($C$4,_d_crystals!$A:$AZ,19,0),"")
B29: MAGICAL USES | C29: =IFERROR(VLOOKUP($C$4,_d_crystals!$A:$AZ,20,0),"")
B31: HERB 2 | C31: =IFERROR(VLOOKUP($C$4,_d_crystals!$A:$AZ,21,0),"")
B32: MAGICAL USES | C32: =IFERROR(VLOOKUP($C$4,_d_crystals!$A:$AZ,22,0),"")
B34: HERB 3 | C34: =IFERROR(VLOOKUP($C$4,_d_crystals!$A:$AZ,23,0),"")
B35: MAGICAL USES | C35: =IFERROR(VLOOKUP($C$4,_d_crystals!$A:$AZ,24,0),"")
B37: HERB 4 | C37: =IFERROR(VLOOKUP($C$4,_d_crystals!$A:$AZ,25,0),"")
B38: MAGICAL USES | C38: =IFERROR(VLOOKUP($C$4,_d_crystals!$A:$AZ,26,0),"")
A41: 🫙 ASSOCIATED OILS
B42: OIL 1 | C42: =IFERROR(VLOOKUP($C$4,_d_crystals!$A:$AZ,43,0),"")
B43: USES | C43: =IFERROR(VLOOKUP($C$4,_d_crystals!$A:$AZ,44,0),"")
B44: SPIRITUAL | C44: =IFERROR(VLOOKUP($C$4,_d_crystals!$A:$AZ,45,0),"")
B46: OIL 2 | C46: =IFERROR(VLOOKUP($C$4,_d_crystals!$A:$AZ,46,0),"")
B47: USES | C47: =IFERROR(VLOOKUP($C$4,_d_crystals!$A:$AZ,47,0),"")
B48: SPIRITUAL | C48: =IFERROR(VLOOKUP($C$4,_d_crystals!$A:$AZ,48,0),"")
B50: OIL 3 | C50: =IFERROR(VLOOKUP($C$4,_d_crystals!$A:$AZ,49,0),"")
B51: USES | C51: =IFERROR(VLOOKUP($C$4,_d_crystals!$A:$AZ,50,0),"")
B52: SPIRITUAL | C52: =IFERROR(VLOOKUP($C$4,_d_crystals!$A:$AZ,51,0),"")
A55: ᚛ ASSOCIATED RUNES
B56: RUNE 1 | C56: =IFERROR(IF(VLOOKUP($C$4,_d_crystals!$A:$AZ,27,0)="","",VLOOKUP($C$4,_d_crystals!$A:$AZ,27,0)&" ("&VLOOKUP($C$4,_d_crystals!$A:$AZ,28,0)&")"),"")
...

Sheet 🫙 Oil Lookup
A2: 🫙 The Greenman Oil Oracle 🫙
A4: 🫙 Select Oil: | C4: Frankincense
A6: 🫙 IDENTITY
A7: =IFERROR("🫙 "&VLOOKUP($C$4,_d_oils!$A:$AR,1,0),"")
A8: =IFERROR("( "&VLOOKUP($C$4,_d_oils!$A:$AR,2,0)&" )","")
A9: =IFERROR("✦ "&VLOOKUP($C$4,_d_oils!$A:$AR,3,0),"")
A11: 🔮 MAGICAL USES
B12: MAGICAL USES | C12: =IFERROR(VLOOKUP($C$4,_d_oils!$A:$AR,4,0),"")
A14: 💫 SPIRITUAL & POWERS
B15: POWERS | C15: =IFERROR(VLOOKUP($C$4,_d_oils!$A:$AR,13,0),"")
B16: SPIRITUAL USES | C16: =IFERROR(VLOOKUP($C$4,_d_oils!$A:$AR,14,0),"")
A18: 📖 CORRESPONDENCES
B19: ASSOCIATION | C19: =IFERROR(VLOOKUP($C$4,_d_oils!$A:$AR,5,0),"")
B20: ELEMENT | C20: =IFERROR(VLOOKUP($C$4,_d_oils!$A:$AR,7,0),"")
B21: ENERGY | C21: =IFERROR(VLOOKUP($C$4,_d_oils!$A:$AR,8,0),"")
B22: DAY | C22: =IFERROR(VLOOKUP($C$4,_d_oils!$A:$AR,9,0),"")
B23: DEITY | C23: =IFERROR(VLOOKUP($C$4,_d_oils!$A:$AR,10,0),"")
B24: SABBAT | C24: =IFERROR(VLOOKUP($C$4,_d_oils!$A:$AR,11,0),"")
B25: PLANET | C25: =IFERROR(VLOOKUP($C$4,_d_oils!$A:$AR,6,0),"")
A27: 🌿 ASSOCIATED HERBS
B28: HERB 1 | C28: =IFERROR(VLOOKUP($C$4,_d_oils!$A:$AR,19,0),"")
B29: MAGICAL USES | C29: =IFERROR(VLOOKUP($C$4,_d_oils!$A:$AR,20,0),"")
B31: HERB 2 | C31: =IFERROR(VLOOKUP($C$4,_d_oils!$A:$AR,21,0),"")
B32: MAGICAL USES | C32: =IFERROR(VLOOKUP($C$4,_d_oils!$A:$AR,22,0),"")
B34: HERB 3 | C34: =IFERROR(VLOOKUP($C$4,_d_oils!$A:$AR,23,0),"")
B35: MAGICAL USES | C35: =IFERROR(VLOOKUP($C$4,_d_oils!$A:$AR,24,0),"")
B37: HERB 4 | C37: =IFERROR(VLOOKUP($C$4,_d_oils!$A:$AR,25,0),"")
B38: MAGICAL USES | C38: =IFERROR(VLOOKUP($C$4,_d_oils!$A:$AR,26,0),"")
A41: ◈ ASSOCIATED CRYSTALS
B42: CRYSTAL 1 | C42: =IFERROR(VLOOKUP($C$4,_d_oils!$A:$AR,27,0),"")
B43: POWERS | C43: =IFERROR(VLOOKUP($C$4,_d_oils!$A:$AR,28,0),"")
B45: CRYSTAL 2 | C45: =IFERROR(VLOOKUP($C$4,_d_oils!$A:$AR,29,0),"")
B46: POWERS | C46: =IFERROR(VLOOKUP($C$4,_d_oils!$A:$AR,30,0),"")
B48: CRYSTAL 3 | C48: =IFERROR(VLOOKUP($C$4,_d_oils!$A:$AR,31,0),"")
B49: POWERS | C49: =IFERROR(VLOOKUP($C$4,_d_oils!$A:$AR,32,0),"")
B51: CRYSTAL 4 | C51: =IFERROR(VLOOKUP($C$4,_d_oils!$A:$AR,33,0),"")
B52: POWERS | C52: =IFERROR(VLOOKUP($C$4,_d_oils!$A:$AR,34,0),"")
A55: ᚛ ASSOCIATED RUNES
B56: RUNE 1 | C56: =IFERROR(IF(VLOOKUP($C$4,_d_oils!$A:$AR,35,0)="","",VLOOKUP($C$4,_d_oils!$A:$AR,35,0)&" ("&VLOOKUP($C$4,_d_oils!$A:$AR,36,0)&")"),"")
B57: USES | C57: =IFERROR(VLOOKUP($C$4,_d_oils!$A:$AR,37,0),"")
...

Sheet ᚛ Rune Lookup
A2: ᚛ The Greenman Runic Oracle ᚛
A4: ᚛ Select Rune: | C4: KAUNO
A6: ᚛ IDENTITY
A7: =IFERROR(VLOOKUP($C$4,_d_runes!$A:$BA,1,0)&" ᚛ "&VLOOKUP($C$4,_d_runes!$A:$BA,3,0),"")
A8: =IFERROR(VLOOKUP($C$4,_d_runes!$A:$BA,2,0),"")
A9: =IFERROR("Pronunciation: "&VLOOKUP($C$4,_d_runes!$A:$BA,4,0)&" · Number: "&VLOOKUP($C$4,_d_runes!$A:$BA,16,0),"")
A11: 🔮 MAGICAL USES
B12: MAGICAL USES | C12: =IFERROR(VLOOKUP($C$4,_d_runes!$A:$BA,5,0),"")
A14: 💫 SPIRITUAL & POWERS
B15: POWERS | C15: =IFERROR(VLOOKUP($C$4,_d_runes!$A:$BA,14,0),"")
B16: SPIRITUAL USES | C16: =IFERROR(VLOOKUP($C$4,_d_runes!$A:$BB,54,0),"")
A18: 📖 CORRESPONDENCES
B19: ASSOCIATION | C19: =IFERROR(VLOOKUP($C$4,_d_runes!$A:$BA,6,0),"")
B20: ELEMENT | C20: =IFERROR(VLOOKUP($C$4,_d_runes!$A:$BA,8,0),"")
B21: ENERGY | C21: =IFERROR(VLOOKUP($C$4,_d_runes!$A:$BA,9,0),"")
B22: DAY | C22: =IFERROR(VLOOKUP($C$4,_d_runes!$A:$BA,10,0),"")
B23: DEITY | C23: =IFERROR(VLOOKUP($C$4,_d_runes!$A:$BA,11,0),"")
B24: SABBAT | C24: =IFERROR(VLOOKUP($C$4,_d_runes!$A:$BA,12,0),"")
B25: PLANET | C25: =IFERROR(VLOOKUP($C$4,_d_runes!$A:$BA,7,0),"")
B26: COLOR | C26: =IFERROR(VLOOKUP($C$4,_d_runes!$A:$BA,17,0),"")
B27: TREE | C27: =IFERROR(VLOOKUP($C$4,_d_runes!$A:$BA,18,0),"")
A29: 🌿 ASSOCIATED HERBS
B30: HERB 1 | C30: =IFERROR(VLOOKUP($C$4,_d_runes!$A:$BA,21,0),"")
B31: MAGICAL USES | C31: =IFERROR(VLOOKUP($C$4,_d_runes!$A:$BA,22,0),"")
B33: HERB 2 | C33: =IFERROR(VLOOKUP($C$4,_d_runes!$A:$BA,23,0),"")
B34: MAGICAL USES | C34: =IFERROR(VLOOKUP($C$4,_d_runes!$A:$BA,24,0),"")
B36: HERB 3 | C36: =IFERROR(VLOOKUP($C$4,_d_runes!$A:$BA,25,0),"")
B37: MAGICAL USES | C37: =IFERROR(VLOOKUP($C$4,_d_runes!$A:$BA,26,0),"")
B39: HERB 4 | C39: =IFERROR(VLOOKUP($C$4,_d_runes!$A:$BA,27,0),"")
B40: MAGICAL USES | C40: =IFERROR(VLOOKUP($C$4,_d_runes!$A:$BA,28,0),"")
A43: ◈ ASSOCIATED CRYSTALS
B44: CRYSTAL 1 | C44: =IFERROR(VLOOKUP($C$4,_d_runes!$A:$BA,33,0),"")
B45: POWERS | C45: =IFERROR(VLOOKUP($C$4,_d_runes!$A:$BA,34,0),"")
B47: CRYSTAL 2 | C47: =IFERROR(VLOOKUP($C$4,_d_runes!$A:$BA,35,0),"")
B48: POWERS | C48: =IFERROR(VLOOKUP($C$4,_d_runes!$A:$BA,36,0),"")
B50: CRYSTAL 3 | C50: =IFERROR(VLOOKUP($C$4,_d_runes!$A:$BA,37,0),"")
B51: POWERS | C51: =IFERROR(VLOOKUP($C$4,_d_runes!$A:$BA,38,0),"")
B53: CRYSTAL 4 | C53: =IFERROR(VLOOKUP($C$4,_d_runes!$A:$BA,39,0),"")
B54: POWERS | C54: =IFERROR(VLOOKUP($C$4,_d_runes!$A:$BA,40,0),"")
A57: 🫙 ASSOCIATED OILS
...

Sheet ☽ Deity Lookup
A2: ☽ The Greenman Deity Oracle ☽
A4: ☽ Select Deity: | C4: AMBERELLA
A6: ☽ IDENTITY
A7: =IFERROR("☽ "&VLOOKUP($C$4,_d_deities!$A:$BD,1,0)&" ☽","")
A8: =IFERROR(VLOOKUP($C$4,_d_deities!$A:$BD,2,0)&" · "&VLOOKUP($C$4,_d_deities!$A:$BD,3,0)&" · "&VLOOKUP($C$4,_d_deities!$A:$BD,7,0),"")
A10: 📖 DESCRIPTION
B11: DESCRIPTION | C11: =IFERROR(VLOOKUP($C$4,_d_deities!$A:$BD,10,0),"")
A13: 🔮 MAGICAL USES
B14: MAGICAL USES | C14: =IFERROR(VLOOKUP($C$4,_d_deities!$A:$BD,8,0),"")
A16: 🌿 GREEN ENERGY
B17: GREEN ENERGY | C17: =IFERROR(VLOOKUP($C$4,_d_deities!$A:$BD,12,0),"")
A19: 📖 ASSOCIATIONS
B20: ELEMENT | C20: =IFERROR(VLOOKUP($C$4,_d_deities!$A:$BD,4,0),"")
B21: PLANET | C21: =IFERROR(VLOOKUP($C$4,_d_deities!$A:$BD,5,0),"")
B22: SACRED DAY | C22: =IFERROR(VLOOKUP($C$4,_d_deities!$A:$BD,6,0),"")
B23: SEASON | C23: =IFERROR(VLOOKUP($C$4,_d_deities!$A:$BD,7,0),"")
B24: POLARITY | C24: =IFERROR(VLOOKUP($C$4,_d_deities!$A:$BD,3,0),"")
B25: TYPE | C25: =IFERROR(VLOOKUP($C$4,_d_deities!$A:$BD,2,0),"")
A27: 🌿 ASSOCIATED HERBS
B28: HERB 1 | C28: =IFERROR(VLOOKUP($C$4,_d_deities!$A:$BD,13,0),"")
B29: MAGICAL USES | C29: =IFERROR(VLOOKUP($C$4,_d_deities!$A:$BD,14,0),"")
B31: HERB 2 | C31: =IFERROR(VLOOKUP($C$4,_d_deities!$A:$BD,15,0),"")
B32: MAGICAL USES | C32: =IFERROR(VLOOKUP($C$4,_d_deities!$A:$BD,16,0),"")
B34: HERB 3 | C34: =IFERROR(VLOOKUP($C$4,_d_deities!$A:$BD,17,0),"")
B35: MAGICAL USES | C35: =IFERROR(VLOOKUP($C$4,_d_deities!$A:$BD,18,0),"")
B37: HERB 4 | C37: =IFERROR(VLOOKUP($C$4,_d_deities!$A:$BD,19,0),"")
B38: MAGICAL USES | C38: =IFERROR(VLOOKUP($C$4,_d_deities!$A:$BD,20,0),"")
B40: HERB 5 | C40: =IFERROR(VLOOKUP($C$4,_d_deities!$A:$BD,21,0),"")
B41: MAGICAL USES | C41: =IFERROR(VLOOKUP($C$4,_d_deities!$A:$BD,22,0),"")
B43: HERB 6 | C43: =IFERROR(VLOOKUP($C$4,_d_deities!$A:$BD,23,0),"")
B44: MAGICAL USES | C44: =IFERROR(VLOOKUP($C$4,_d_deities!$A:$BD,24,0),"")
A47: ◈ ASSOCIATED CRYSTALS
B48: CRYSTALS | C48: =IFERROR(VLOOKUP($C$4,_d_deities!$A:$BD,53,0),"")
A50: 🫙 ASSOCIATED OILS
B51: OILS | C51: =IFERROR(VLOOKUP($C$4,_d_deities!$A:$BD,54,0),"")
A53: ᚛ ASSOCIATED RUNES
B54: RUNE 1 | C54: =IFERROR(IF(VLOOKUP($C$4,_d_deities!$A:$BD,41,0)="","",VLOOKUP($C$4,_d_deities!$A:$BD,41,0)&" ("&VLOOKUP($C$4,_d_deities!$A:$BD,42,0)&")"),"")
B55: MAGICAL USES | C55: =IFERROR(VLOOKUP($C$4,_d_deities!$A:$BD,43,0),"")
B57: RUNE 2 | C57: =IFERROR(IF(VLOOKUP($C$4,_d_deities!$A:$BD,44,0)="","",VLOOKUP($C$4,_d_deities!$A:$BD,44,0)&" ("&VLOOKUP($C$4,_d_deities!$A:$BD,45,0)&")"),"")
B58: MAGICAL USES | C58: =IFERROR(VLOOKUP($C$4,_d_deities!$A:$BD,46,0),"")
...

Sheet 📋 How To Use
A2: ✦ The Greenman Magical Database ✦
A4: 📋 How To Use
A6: Use the dropdown on each sheet to select an entry. All fields update instantly.
A8: Contents
A9: 🌿 Herb Lookup — 106 herbs · magical uses · correspondences · oils, crystals & runes linked
A11: ◈ Crystal Lookup — 65 crystals · powers & spiritual uses · linked herbs & runes · geology
A13: 🫙 Oil Lookup — 29 oils · magical & spiritual uses · linked herbs & crystals · folk lore
A15: ᚛ Rune Lookup — 24 runes · all correspondences · every linked herb, crystal & oil
A18: ✦ The Greenman Magical Database

Sheet Index
A1: The Greenman Magic — Workbook Index
A2: A complete magical reference database — herbs, crystals, oils, runes, deities, elements, candles, numerology, planetary hours
A3: Sheet Name | B3: Purpose | C3: Rows of Data | D3: Key Columns | E3: Notes
A4: Index | B4: Navigation overview of entire workbook | C4: — | D4: Sheet Name, Purpose, Key Columns, Notes | E4: You are here
A5: Spell Types | B5: 60 spell and charm types with moon phase guidance | C5: 60 | D5: Category, Spell/Charm Type, Moon Phase | E5: Anchor list for spell builder logic
A6: Herbs | B6: 106 herbs with full magical, folkloric and elemental profiles | C6: 106 | D6: Name, Ye Olde Name, Latin Name, Magical Uses, Association, Planet, Element, Energy, Day, Deity, Sabbat, Folk Lore, Powers, Spiritual Uses, Description, Oil Name, Geology, Warning | E6: Core ingredient database. Warnings highlighted in amber.
A7: Crystals | B7: 65 crystals with magical properties, deity links and spiritual uses | C7: 65 | D7: Name, Ye Olde Name, Latin Name, Magical Uses, Association, Planet, Element, Energy, Day, Deity, Sabbat, Folk Lore, Powers, Spiritual Uses, Description, Oil Name, Geology, Warning | E7: Shares column structure with Herbs
A8: Oils | B8: 29 magical oils with planetary, deity and sabbat correspondences | C8: 29 | D8: Name, Ye Olde Name, Latin Name, Magical Uses, Association, Planet, Element, Energy, Day, Deity, Sabbat, Folklore, Powers, Spiritual Uses, Description, Oil Name, Geology, Warning | E8: Selected separately in spell construction
A9: Runes | B9: 24 runes with full runic profile, associated herbs and crystals | C9: 24 | D9: Name, Ye Olde Name, Letter, Pronunciation, Magical Uses, Association, Planet, Element, Energy, Day, Deity, Sabbat, Folk Lore, Powers, Description, Runic Number, Color, Tree, Associated Herbs, Associated Crystals | E9: Cross-reference columns link to herbs and crystals
A10: Deities | B10: 87 deities with magical profile, green energy and sacred associations | C10: 87 | D10: Name/Entity, Type, Polarity, Element, Planet, Sacred Day, Season, Magical Uses, Associated Herbs, Description, Famous Magic, Green Energy | E10: Master deity reference
A11: Elements | B11: 4 classical elements with direction, gender, energy and colours | C11: 4 | D11: Element, Gender, Direction, Energy, Colors | E11: Reference for elemental herb filtering
A12: Candles | B12: 13 candle colours with magical purpose and intention | C12: 13 | D12: Color, Magical Purpose | E12: Match candle colour to spell intention
A13: Numerology | B13: 9 numerological numbers with planetary and elemental links | C13: 9 | D13: Number, Planet, Element, Letters, Energies | E13: Links numbers to planets and elements
A14: Planets | B14: 168 planetary hour entries — ruling planet by day and hour | C14: 168 | D14: Day, Description, Planet | E14: Full 7-day planetary hour table from sunrise

Sheet Spell Types
A1: Category | B1: Spell/Charm Type | C1: Moon Phase | D1: Element | E1: Planet | F1: Sacred Day | G1: Candle Colour | H1: Elemental Direction | I1: Elemental Energy | J1: Elemental Colors | K1: Numerology Number | L1: Numerology Energies | M1: Herb Count | N1: Matching Herbs | O1: Herb Count Total | P1: Matching Crystals | Q1: Crystal Count | R1: Matching Oils | S1: Oil Count | T1: Matching Runes | U1: Rune Count | V1: Matching Deities | W1: Deity Count | X1: Greenman Energy Mode | Y1: Secondary Energy Hint | Z1: Recommended Spell Method | AA1: Jar Allowed | AB1: Smoke and Flame Allowed | AC1: Charm Bag Allowed | AD1: Wording Focus | AE1: Instruction Notes | AF1: Primary Placement | AG1: Other Placements
A2: Over 18 🔞 | B2: Aphrodisiac | C2: Waxing | D2: Fire | E2: Mars | F2: Tuesday | G2: Red | H2: South | I2: Projective | J2: Red, gold, crimson, orange, white | K2: 9 | L2: Aggression, conflict, dominance | M2: 1, 3 or 7 | N2: ACORN, BLACKBERRY LEAVES, CALAMUS ROOT, CARAWAY, CLOVER RED, GINGER ROOT, HIBISCUS, LADIES MANTLE, MUSTARD SEED WHITE, VIOLET LEAVES | O2: 10 | P2: Carnelian, Garnet, Lodestone, Red Jasper, Ruby, Unakite | Q2: 6 | R2: Vanilla, Ylang Ylang, Patchouli | S2: 3 | T2: FEHU, URUZ, GEBO, BERKANAN | U2: 4 | V2: AESCULAPUS, ALL GODDESSES, AMBERELLA, APHRODITE, ARADIA, ASTARTE, ATTIS, BALDUR & HATHOR, BONA DEA, CEBELE, CUPID, CYBELE, EROS, HATHOR, HECATE, JANA, JUPITER, KWAI-YIN, KWAN-YIN AND BUDDHA, LUNA | W2: 29 | X2: Over 18 | Y2: Draw | Z2: All Three / User Choice | AA2: Yes | AB2: Yes | AC2: Yes | AD2: Adult / serious working: let the user choose Jar, Smoke and Flame, or Charm after reading the method notes. | AE2: App should pull this row's Greenman Energy Mode from the main item sheets. Use Secondary Energy Hint only if a serious/adult spell still needs a Draw/Hold/Release/Open/Transform flavour. | AF2: Carry it close on your person | AG2: Gift to the intended | Place where it can be seen
A3: Attraction, Love & Relationships | B3: Attraction | C3: Waxing | D3: Water | E3: Venus | F3: Friday | G3: Pink | H3: West | I3: Receptive | J3: Blue, turquoise, green, grey, indigo, black | K3: 6 | L3: Emotions, magnetism, gods/goddesses, cats | M3: 1, 3 or 7 | N3: GOLDENROD, GOLDENSEAL ROOT, JASMINE, ROSE BUDS RED, ROSE PETALS, RUE | O3: 6 | P3: quartz Rose, Moonstone, Carnelian, Lapis Lazuli | Q3: 4 | R3: Clove Bud, Cinnamon | S3: 2 | T3: FEHU, GEBO | U3: 2 | V3: AESCULAPUS, ALL GODDESSES, AMBERELLA, APHRODITE, ARADIA, ASTARTE, ATTIS, BALDUR & HATHOR, BONA DEA, CEBELE, CUPID, CYBELE, EROS, HATHOR, HECATE, JANA, JUPITER, KWAI-YIN, KWAN-YIN AND BUDDHA, LUNA | W3: 28 | X3: Draw | Y3: Draw | Z3: Spell Jar | AA3: Yes | AB3: Maybe | AC3: Yes | AD3: Draw, grow, sweeten, settle or carry relationship energy. | AE3: App should pull this row's Greenman Energy Mode from the main item sheets. Use Secondary Energy Hint only if a serious/adult spell still needs a Draw/Hold/Release/Open/Transform flavour. | AF3: Carry it close on your person | AG3: Gift to the intended | Place where it can be seen | Hang it in the home
A4: Attraction, Love & Relationships | B4: Exploring feelings | C4: Waxing | D4: Water | E4: Moon | F4: Monday | G4: Blue | H4: West | I4: Receptive | J4: Blue, turquoise, green, grey, indigo, black | K4: 2 | L4: Duality, balance, couples, partnerships | M4: 1, 3 or 7 | N4: LAVENDER FLOWERS, CHAMOMILE, VIOLET LEAVES, LEMON BALM, ROSE PETALS, YARROW, HEARTSEASE | O4: 7 | P4: Moonstone, Amethyst, Rhodocrosite, Lepidolite | Q4: 4 | R4: Lavender, Rose, Melissa, Geranium | S4: 4 | T4: LAGUZ, PERTH, MANNAZ, ANSUZ | U4: 4 | V4: SELENE, LUNA, PERSEPHONE, ISIS, ODIN, MERCURY, SATURN, PLUTO | W4: 8 | X4: Open / Reveal | Y4: Open / Reveal | Z4: Spell Jar | AA4: Yes | AB4: Maybe | AC4: Yes | AD4: Draw, grow, sweeten, settle or carry relationship energy. | AE4: App should pull this row's Greenman Energy Mode from the main item sheets. Use Secondary Energy Hint only if a serious/adult spell still needs a Draw/Hold/Release/Open/Transform flavour. | AF4: Carry it close on your person | AG4: Place where it can be seen | Hang it in the home
A5: Over 18 🔞 | B5: Fertility | C5: Waxing | D5: Earth | E5: Moon | F5: Monday | G5: Green | H5: North | I5: Receptive | J5: Black, green, yellow, brown | K5: 2 | L5: Duality, balance, couples, partnerships | M5: 1, 3 or 7 | N5: ACORN, ANISE, BASIL, BENZOIN, BLACK TEA, BLACKBERRY LEAVES, CARAWAY, CHAMOMILE, CINNAMON STICKS, CLOVER, CLOVER RED, CLOVES, COLTSFOOT, COMFREY, DILL, FENNEL (SEED), GARLIC POWDER, GOLDENSEAL ROOT, JASMINE, LADIES MANTLE, LAVENDER FLOWERS, LEMON BALM, LINSEED, MUSTARD SEED WHITE, NUTMEG POWDER, OAK MOSS, OAKBARK RED, PARSLEY, PEPPERMINT, PINE NUT, RUE, SAGE, THYME, VIOLET LEAVES, VIOLET | O5: 35 | P5: agate Botswana , agate Moss , Amazonite, Aventurine, Calcite, chrysophase, Citrine, Goldstone, Jade (jadeite), Lodestone, Pyrite (Fool's Gold), Rhodocrosite, Ruby, Sapphire, Serpentine, Topaz, Tourmalinee Black , Yellow Aventurine | Q5: 18 | R5: Bergamot, Cedarwood, Clove Bud, Geranium, Honeysuckle, Marjoram, Melissa, Neroli, Orange Bitter, Pine, Vanilla, Cinnamon, Ginger, Patchouli | S5: 14 | T5: FEHU, URUZ, WUNJO, JERA, SOWILO, BERKANAN, INGWAZ, OTHILA, DAGAZ | U5: 9 | V5: ALL GODDESSES, ALL LUNAR GODDESSES, ALLAT, AMATERASU, ARADIA, ARIANRHOD, ASTARTE, ATTIS, BAAL, BALDUR & HATHOR, BONA DEA, CERES, CERRIDWEN, CRONOS, CUPRA, EROS, FILDIAS, GAIA, GOD AND GODDESS IN BALANCE, GREAT GODDESS. MANASA | W5: 34 | X5: Over 18 | Y5: Draw | Z5: All Three / User Choice | AA5: Yes | AB5: Yes | AC5: Yes | AD5: Adult / serious working: let the user choose Jar, Smoke and Flame, or Charm after reading the method notes. | AE5: App should pull this row's Greenman Energy Mode from the main item sheets. Use Secondary Energy Hint only if a serious/adult spell still needs a Draw/Hold/Release/Open/Transform flavour. | AF5: Carry it close on your person | AG5: Bury in the earth | Place at a shrine or altar
A6: Attraction, Love & Relationships | B6: Fidelity | C6: Waxing | D6: Earth | E6: Venus | F6: Friday | G6: Pink | H6: North | I6: Receptive | J6: Black, green, yellow, brown | K6: 6 | L6: Emotions, magnetism, gods/goddesses, cats | M6: 1, 3 or 7 | N6: BASIL, CARAWAY, CLOVER, CLOVER RED, COMFREY, HIBISCUS, ORRIS ROOT POWDER, ROSEMARY, VIOLET LEAVES, VIOLET | O6: 10 | P6: Emerald, Lodestone, quartz Rose | Q6: 3 | R6: Lavender, Rose, Ylang Ylang | S6: 3 | T6: EHWAZ | U6: 1 | V6: VENUS, APHRODITE, HATHOR, FRIGG, FREY, JUPITER, ODIN | W6: 7 | X6: Hold | Y6: Hold | Z6: Spell Jar | AA6: Yes | AB6: Maybe | AC6: Yes | AD6: Draw, grow, sweeten, settle or carry relationship energy. | AE6: App should pull this row's Greenman Energy Mode from the main item sheets. Use Secondary Energy Hint only if a serious/adult spell still needs a Draw/Hold/Release/Open/Transform flavour. | AF6: Keep it hidden and safe | AG6: Hang it in the home | Bury in the earth
A7: Attraction, Love & Relationships | B7: Love | C7: Waxing | D7: Water | E7: Venus | F7: Friday | G7: Pink | H7: West | I7: Receptive | J7: Blue, turquoise, green, grey, indigo, black | K7: 6 | L7: Emotions, magnetism, gods/goddesses, cats | M7: 1, 3 or 7 | N7: ANISE, APPLE BLOSSOM, APPLEWOOD CHIPS, BASIL, BAY LAUREL, BENZOIN, BLACK TEA, BLACKBERRY LEAVES, CALAMUS ROOT, CARAWAY, CEDARWOOD (HIMALAYAN), CHAMOMILE, CHRYSANTHEMUM, CINNAMON STICKS, CLOVER, CLOVER RED, CLOVES, COLTSFOOT, COMFREY, DILL, DRAGON'S BLOOD, ELDERFLOWER, FENNEL (SEED), FRANKINCENSE, GARDENIA FRUIT, GINGER ROOT, GOLDENROD, HEARTSEASE, HIBISCUS, HOREHOUND, HYSSOP, JASMINE, JUNIPER BERRIES, LADIES MANTLE, LAVENDER FLOWERS, LEMON BALM, LEMON VERBENA, LEMONGRASS, LINDEN, MEADOW SWEET, HONESTY, MULLEIN, MUSTARD SEED WHITE, MYRRH GUM, NUTMEG POWDER, OAKBARK RED, SWEET MYRRH, OREGANO, ORRIS ROOT POWDER, PARSLEY, PENNYROYAL, PEPPERMINT, PINE NUT, RASPBERRY LEAF, ROSE BUDS PINK, ROSE BUDS RED, ROSE HIP, ROSE PETALS, ROSEMARY, RUE, SAGE, SANDALWOOD RED, SANDALWOOD WHITE, THYME, VALERIAN ROOT, VIOLET LEAVES, VIOLET | O7: 67 | P7: agate Blue Lace , Amethyst, Apache Tears, Calcite, Carnelian, Chrysocolla, Quartz Clear , Copper flakes, Emerald, Flourite, Hematite, Howlite, Jet, Lapis Lazuli, Lepidolite, Lodestone, Moonstone, Peridot, quartz Rose , quartz smokey , quartz snow , Red Jasper, Rhodonite, Ruby, Sapphire, Seraphinite, Serpentine, Sodalite, Tanzanite, Tiger Eye gold, Unakite, Yellow Aventurine | Q7: 32 | R7: Apple, Bergamot, Clove Bud, Frankincense, Geranium, Juniper, Lavender, Lemon, Lemon Grass, Marjoram, Melissa, Neroli, Orange Bitter, Pine, Rose, Rosemary, Thyme, Vanilla, Ylang Ylang, Cinnamon, Ginger, Patchouli, Sandalwood In. | S7: 23 | T7: FEHU, ANSUZ, RAIDO, GEBO, WUNJO, PERTH, SOWILO, TIWAZ, EHWAZ, INGWAZ, OTHILA | U7: 11 | V7: AESCULAPUS, ALL, ALL GODDESSES, ALL LUNAR GODDESSES, ALLAT, AMATERASU, AMBERELLA, APHRODITE, ARADIA, ARES, ARIANRHOD, ARTEMIS, ASTARTE, ATTIS, BAAL, BACCHUS, BALDOR, BALDUR & HATHOR, BEFANA, BONA DEA | W7: 89 | X7: Draw | Y7: Draw | Z7: Spell Jar | AA7: Yes | AB7: Maybe | AC7: Yes | AD7: Draw, grow, sweeten, settle or carry relationship energy. | AE7: App should pull this row's Greenman Energy Mode from the main item sheets. Use Secondary Energy Hint only if a serious/adult spell still needs a Draw/Hold/Release/Open/Transform flavour. | AF7: Place where it can be seen | AG7: Gift to the intended | Bury in the earth | Hang it in the home
A8: Attraction, Love & Relationships | B8: Love rituals | C8: Waxing | D8: Water | E8: Venus | F8: Friday | G8: Pink | H8: West | I8: Receptive | J8: Blue, turquoise, green, grey, indigo, black | K8: 6 | L8: Emotions, magnetism, gods/goddesses, cats | M8: 1, 3 or 7 | N8: ANISE, APPLE BLOSSOM, APPLEWOOD CHIPS, BASIL, BAY LAUREL, BENZOIN, BLACK TEA, BLACKBERRY LEAVES, CALAMUS ROOT, CARAWAY, CEDARWOOD (HIMALAYAN), CHAMOMILE, CHRYSANTHEMUM, CINNAMON STICKS, CLOVER, CLOVER RED, CLOVES, COLTSFOOT, COMFREY, DILL, DRAGON'S BLOOD, ELDERFLOWER, FENNEL (SEED), FRANKINCENSE, GARDENIA FRUIT, GINGER ROOT, GOLDENROD, HEARTSEASE, HIBISCUS, HOREHOUND, HYSSOP, JASMINE, JUNIPER BERRIES, LADIES MANTLE, LAVENDER FLOWERS, LEMON BALM, LEMON VERBENA, LEMONGRASS, LINDEN, MEADOW SWEET, HONESTY, MULLEIN, MUSTARD SEED WHITE, MYRRH GUM, NUTMEG POWDER, OAKBARK RED, SWEET MYRRH, OREGANO, ORRIS ROOT POWDER, PARSLEY, PENNYROYAL, PEPPERMINT, PINE NUT, RASPBERRY LEAF, ROSE BUDS PINK, ROSE BUDS RED, ROSE HIP, ROSE PETALS, ROSEMARY, RUE, SAGE, SANDALWOOD RED, SANDALWOOD WHITE, THYME, VALERIAN ROOT, VIOLET LEAVES, VIOLET, WHEAT GRAINS | O8: 68 | P8: agate Blue Lace , Amethyst, Apache Tears, Calcite, Carnelian, Chrysocolla, Quartz Clear , Copper flakes, Emerald, Flourite, Hematite, Howlite, Jet, Lapis Lazuli, Lepidolite, Lodestone, Moonstone, Peridot, quartz Rose , quartz smokey , quartz snow , Red Jasper, Rhodonite, Ruby, Sapphire, Seraphinite, Serpentine, Sodalite, Tanzanite, Tiger Eye gold, Unakite, Yellow Aventurine | Q8: 32 | R8: Apple, Bergamot, Clove Bud, Frankincense, Geranium, Juniper, Lavender, Lemon, Lemon Grass, Marjoram, Melissa, Neroli, Orange Bitter, Pine, Rose, Rosemary, Thyme, Vanilla, Ylang Ylang, Cinnamon, Ginger, Patchouli, Sandalwood In. | S8: 23 | T8: FEHU, ANSUZ, RAIDO, GEBO, WUNJO, PERTH, SOWILO, TIWAZ, EHWAZ, INGWAZ, OTHILA | U8: 11 | V8: AESCULAPUS, ALL, ALL GODDESSES, ALL LUNAR GODDESSES, ALLAT, AMATERASU, AMBERELLA, APHRODITE, ARADIA, ARES, ARIANRHOD, ARTEMIS, ASTARTE, ATTIS, BAAL, BACCHUS, BALDOR, BALDUR & HATHOR, BEFANA, BONA DEA | W8: 89 | X8: Draw | Y8: Draw | Z8: Spell Jar | AA8: Yes | AB8: Maybe | AC8: Yes | AD8: Draw, grow, sweeten, settle or carry relationship energy. | AE8: App should pull this row's Greenman Energy Mode from the main item sheets. Use Secondary Energy Hint only if a serious/adult spell still needs a Draw/Hold/Release/Open/Transform flavour. | AF8: Place at a shrine or altar | AG8: Place where it can be seen | Gift to the intended | Carry it close on your person
A9: Attraction, Love & Relationships | B9: Love spells | C9: Waxing | D9: Water | E9: Venus | F9: Friday | G9: Pink | H9: West | I9: Receptive | J9: Blue, turquoise, green, grey, indigo, black | K9: 6 | L9: Emotions, magnetism, gods/goddesses, cats | M9: 1, 3 or 7 | N9: ROSE PETALS, LAVENDER FLOWERS, JASMINE, ROSE BUDS RED, ORRIS ROOT POWDER, VIOLET LEAVES, YARROW | O9: 7 | P9: quartz Rose, Moonstone, Emerald, Lapis Lazuli | Q9: 4 | R9: Rose, Ylang Ylang, Neroli, Lavender | S9: 4 | T9: FEHU, GEBO, WUNJO, BERKANAN | U9: 4 | V9: APHRODITE, VENUS, HATHOR, FREYJA, EROS, FREY, CUPID, DIANA | W9: 8 | X9: Draw | Y9: Draw | Z9: Spell Jar | AA9: Yes | AB9: Maybe | AC9: Yes | AD9: Draw, grow, sweeten, settle or carry relationship energy. | AE9: App should pull this row's Greenman Energy Mode from the main item sheets. Use Secondary Energy Hint only if a serious/adult spell still needs a Draw/Hold/Release/Open/Transform flavour. | AF9: Place where it can be seen | AG9: Gift to the intended | Bury in the earth
A10: Protection, Banishing & Warding | B10: Anti-theft | C10: Waning | D10: Earth | E10: Saturn | F10: Saturday | G10: Black | H10: North | I10: Receptive | J10: Black, green, yellow, brown | K10: 8 | L10: Material aspects, travel, protection, discipline | M10: 1, 3 or 7 | N10: BASIL, CARAWAY, COMFREY, DILL, JUNIPER BERRIES, ROSEMARY | O10: 6 | P10: Jet, Obsidian, Onyx, Tiger Eye gold | Q10: 4 | R10: Frankincense, Cedarwood, Rosemary | S10: 3 | T10: FEHU, GEBO | U10: 2 | V10: GREAT GODDESS. MANASA, PLUTO | W10: 2 | X10: Hold | Y10: Hold | Z10: Spell Jar | AA10: Yes | AB10: Maybe | AC10: Yes | AD10: Hold boundaries, guard, ward and keep protection steady. | AE10: App should pull this row's Greenman Energy Mode from the main item sheets. Use Secondary Energy Hint only if a serious/adult spell still needs a Draw/Hold/Release/Open/Transform flavour. | AF10: Keep it hidden and safe | AG10: Hang it in the home | Bury in the earth
A11: Over 18 🔞 | B11: Banishing | C11: Waning/Dark | D11: Fire | E11: Mars | F11: Tuesday | G11: Black | H11: South | I11: Projective | J11: Red, gold, crimson, orange, white | K11: 9 | L11: Aggression, conflict, dominance | M11: 1, 3 or 7 | N11: AGRIMONY, ANISE, BASIL, BAY LAUREL, CAMPHOR SYNTHETIC, CEDARWOOD (HIMALAYAN), CHIVE, CLOVER, CLOVER RED, CLOVES, COMFREY, DEVILS CLAW ROOT, DRAGON'S BLOOD, FRANKINCENSE, GARLIC POWDER, HOREHOUND, HYSSOP, JUNIPER BERRIES, LAVENDER FLOWERS, LEMON VERBENA, LEMONGRASS, MULLEIN, MUSTARD SEED WHITE, MYRRH GUM, OAKLEAF, PENNYROYAL, PEPPERMINT, PINE NUT, ROSE HIP, ROSEMARY, RUE, SAGE, SANDALWOOD RED, SANDALWOOD WHITE, SEA SALT, THYME, VALERIAN ROOT, VERVAIN, VIOLET, WITCH HAZEL LEAVES, BLACK SALT, WORMWOOD | O11: 42 | P11: Aquamarine, Hematite, Lepidolite, Obsidian, quartz smokey , quartz snow , Serpentine, Tourmalinee Black | Q11: 8 | R11: Fir Needle, Frankincense, Lemon Grass, Sandalwood w.i., Tea Tree, Ylang Ylang | S11: 6 | T11: THURISAZ, HAGALAZ, IHWAZ, ALGIZ, LAGUZ | U11: 5 | V11: AMBERELLA, ARTEMIS, BALDOR, CUPRA, DIANA, FLIDAIS, HECATE, HEL, HYGIA, ISIS, JUTERNA, KWAN-YIN AND BUDDHA, LUNA, MARS, SHIVA, THOR, ZEUS | W11: 17 | X11: Over 18 | Y11: Release | Z11: All Three / User Choice | AA11: Yes | AB11: Yes | AC11: Yes | AD11: Adult / serious working: let the user choose Jar, Smoke and Flame, or Charm after reading the method notes. | AE11: App should pull this row's Greenman Energy Mode from the main item sheets. Use Secondary Energy Hint only if a serious/adult spell still needs a Draw/Hold/Release/Open/Transform flavour. | AF11: Bury in the earth | AG11: Burn and release, no remains | Leave in running water
A12: Over 18 🔞 | B12: Exorcism | C12: Waning/Dark | D12: Fire | E12: Mars | F12: Tuesday | G12: Red | H12: South | I12: Projective | J12: Red, gold, crimson, orange, white | K12: 9 | L12: Aggression, conflict, dominance | M12: 1, 3 or 7 | N12: AGRIMONY, ANISE, BASIL, BAY LAUREL, CAMPHOR SYNTHETIC, CEDARWOOD (HIMALAYAN), CHIVE, CLOVER, CLOVER RED, CLOVES, COMFREY, DEVILS CLAW ROOT, DRAGON'S BLOOD, FRANKINCENSE, GARLIC POWDER, HOREHOUND, HYSSOP, JUNIPER BERRIES, LAVENDER FLOWERS, LEMON VERBENA, LEMONGRASS, MULLEIN, MUSTARD SEED WHITE, MYRRH GUM, OAKLEAF, PENNYROYAL, PEPPERMINT, PINE NUT, ROSE HIP, ROSEMARY, RUE, SAGE, SANDALWOOD RED, SANDALWOOD WHITE, SEA SALT, THYME, VALERIAN ROOT, VERVAIN, VIOLET, WITCH HAZEL LEAVES, BLACK SALT | O12: 41 | P12: Aquamarine, Hematite, Lepidolite, Obsidian, quartz smokey , quartz snow , Serpentine, Tourmalinee Black | Q12: 8 | R12: Fir Needle, Frankincense, Lemon Grass, Sandalwood w.i., Tea Tree, Ylang Ylang | S12: 6 | T12: THURISAZ, HAGALAZ, IHWAZ, ALGIZ, LAGUZ | U12: 5 | V12: AMBERELLA, ARTEMIS, BALDOR, CUPRA, DIANA, FLIDAIS, HECATE, HEL, HYGIA, ISIS, JUTERNA, KWAN-YIN AND BUDDHA, LUNA, MARS, SHIVA, THOR, ZEUS | W12: 17 | X12: Over 18 | Y12: Release | Z12: All Three / User Choice | AA12: Yes | AB12: Yes | AC12: Yes | AD12: Adult / serious working: let the user choose Jar, Smoke and Flame, or Charm after reading the method notes. | AE12: App should pull this row's Greenman Energy Mode from the main item sheets. Use Secondary Energy Hint only if a serious/adult spell still needs a Draw/Hold/Release/Open/Transform flavour. | AF12: Burn and release, no remains | AG12: Bury in the earth
A13: Protection, Banishing & Warding | B13: Nightmare prevention | C13: Waning | D13: Air | E13: Moon | F13: Monday | G13: White | H13: East | I13: Projective | J13: Yellow, white, crimson | K13: 2 | L13: Duality, balance, couples, partnerships | M13: 1, 3 or 7 | N13: ANISE, CHAMOMILE, DILL, GARLIC POWDER, JASMINE, LAVENDER FLOWERS, MULLEIN, OAKBARK RED, PEPPERMINT, ROSEMARY, THYME, VALERIAN ROOT | O13: 12 | P13: Lepidolite, Red Jasper, Ruby | Q13: 3 | R13: Cedarwood | S13: 1 | T13: LAGUZ | U13: 1 | V13: SELENE, LUNA, HECATE, DIANA, ODIN, SATURN, MERCURY | W13: 7 | X13: Hold | Y13: Hold | Z13: Spell Jar | AA13: Yes | AB13: Maybe | AC13: Yes | AD13: Hold boundaries, guard, ward and keep protection steady. | AE13: App should pull this row's Greenman Energy Mode from the main item sheets. Use Secondary Energy Hint only if a serious/adult spell still needs a Draw/Hold/Release/Open/Transform flavour. | AF13: Keep it hidden and safe | AG13: Hang it in the home | Carry it close on your person
A14: Protection, Banishing & Warding | B14: Protection | C14: Waning | D14: Fire | E14: Mars | F14: Tuesday | G14: Red | H14: South | I14: Projective | J14: Red, gold, crimson, orange, white | K14: 9 | L14: Aggression, conflict, dominance | M14: 1, 3 or 7 | N14: ACORN, AGRIMONY, ANISE, BASIL, BAY LAUREL, BLACKBERRY LEAVES, CARAWAY, CEDARWOOD (HIMALAYAN), CINNAMON STICKS, CLOVER, CLOVES, DEVILS CLAW ROOT, DILL, ELDERFLOWER, FENNEL (SEED), GARLIC POWDER, HOREHOUND, HYSSOP, JUNIPER BERRIES, LADIES MANTLE, LAVENDER FLOWERS, MULLEIN, MUSTARD SEED WHITE, MYRRH GUM, NETTLE, OAKBARK RED, SWEET MYRRH, OREGANO, PARSLEY, PENNYROYAL, PEPPERMINT, PINE NUT, RASPBERRY LEAF, ROSE BUDS RED, ROSEMARY, RUE, SANDALWOOD RED, SANDALWOOD WHITE, ST JOHN'S WORT, THYME, VALERIAN ROOT, VERVAIN, VIOLET LEAVES, VIOLET, WILLOW BARK, WINTERGREEN, WITCH HAZEL BARK, WITCH HAZEL LEAVES, BLACK SALT | O14: 49 | P14: Amethyst, Apache Tears, Aquamarine, Aventurine, chrysophase, Quartz Clear , Emerald, Garnet, Hematite, Iolite, Jade (jadeite), Jet, Labradorite, Lapis Lazuli, Malachite, Obsidian, obsidian snowflake, Onyx, Opal pink, Peridot, quartz rutilated , quartz smokey , Red Jasper, Ruby, Sodalite, Tiger Eye gold, Tourmalinee Black , Turquoise, Amber | Q14: 29 | R14: Cedarwood, Clove Bud, Fir Needle, Frankincense, Geranium, Honeysuckle, Juniper, Marjoram, Pine, Rose, Rosemary, Sandalwood w.i., Tea Tree, Ylang Ylang, Cinnamon, Sandalwood In. | S14: 16 | T14: URUZ, THURISAZ, HAGALAZ, ISA, IHWAZ, ALGIZ, TIWAZ, OTHILA | U14: 8 | V14: AMBERELLA, ARTEMIS, BALDOR, CUPRA, DIANA, FLIDAIS, HECATE, HYGIA, ISIS, KWAN-YIN AND BUDDHA, LUNA, MARS, SECH, SHIVA, THE GREAT MOTHER, THOR, ZEUS, FRIGG, HOLDA | W14: 19 | X14: Hold | Y14: Hold | Z14: Spell Jar | AA14: Yes | AB14: Maybe | AC14: Yes | AD14: Hold boundaries, guard, ward and keep protection steady. | AE14: App should pull this row's Greenman Energy Mode from the main item sheets. Use Secondary Energy Hint only if a serious/adult spell still needs a Draw/Hold/Release/Open/Transform flavour. | AF14: Carry it close on your person | AG14: Hang it in the home | Keep it hidden and safe | Bury in the earth
A15: Over 18 🔞 | B15: Protection (hexes/evil) | C15: Waning | D15: Fire | E15: Mars | F15: Tuesday | G15: Black | H15: South | I15: Projective | J15: Red, gold, crimson, orange, white | K15: 9 | L15: Aggression, conflict, dominance | M15: 1, 3 or 7 | N15: AGRIMONY, ANISE, BASIL, BAY LAUREL, CHIVE, CLOVES, COLTSFOOT, DILL, DRAGON'S BLOOD, ELDERFLOWER, FENNEL (SEED), GINGER ROOT, HOREHOUND, LAVENDER FLOWERS, LEMONGRASS, LINSEED, MULLEIN, MUSTARD SEED WHITE, MYRRH GUM, OAKLEAF, SWEET MYRRH, PENNYROYAL, PEPPERMINT, PINE NUT, ROSEMARY, RUE, SAGE, SANDALWOOD RED, TANSY, VERVAIN, BLACK SALT | O15: 31 | P15: Obsidian, obsidian snowflake, Tourmalinee Black , Turquoise, Amber | Q15: 5 | R15: Frankincense | S15: 1 | T15: THURISAZ, KAUNO, HAGALAZ, ALGIZ | U15: 4 | V15: AESCULAPUS, AMATERASU, AMBERELLA, ARTEMIS, ASTARTE, BALDOR, BONA DEA, BRIGID, CUPRA, DIANA, DIONYSUS, FLIDAIS, HECATE, HYGIA, ISIS, JUTERNA, KWAI-YIN, KWAN-YIN AND BUDDHA, LUNA, MARS | W15: 28 | X15: Over 18 | Y15: Hold | Z15: All Three / User Choice | AA15: Yes | AB15: Yes | AC15: Yes | AD15: Adult / serious working: let the user choose Jar, Smoke and Flame, or Charm after reading the method notes. | AE15: App should pull this row's Greenman Energy Mode from the main item sheets. Use Secondary Energy Hint only if a serious/adult spell still needs a Draw/Hold/Release/Open/Transform flavour. | AF15: Carry it close on your person | AG15: Hang it in the home | Keep it hidden and safe
A16: Protection, Banishing & Warding | B16: Warding | C16: Waning | D16: Earth | E16: Saturn | F16: Saturday | G16: Black | H16: North | I16: Receptive | J16: Black, green, yellow, brown | K16: 8 | L16: Material aspects, travel, protection, discipline | M16: 1, 3 or 7 | N16: AGRIMONY, ANISE, BASIL, BAY LAUREL, CHIVE, CLOVES, COLTSFOOT, DILL, DRAGON'S BLOOD, ELDERFLOWER, FENNEL (SEED), GINGER ROOT, HOREHOUND, LAVENDER FLOWERS, LEMONGRASS, LINSEED, MULLEIN, MUSTARD SEED WHITE, MYRRH GUM, OAKLEAF, SWEET MYRRH, PENNYROYAL, PEPPERMINT, PINE NUT, ROSEMARY, RUE, SAGE, SANDALWOOD RED, TANSY, VERVAIN, BLACK SALT | O16: 31 | P16: Obsidian, obsidian snowflake, Tourmalinee Black , Turquoise, Amber | Q16: 5 | R16: Frankincense | S16: 1 | T16: THURISAZ, KAUNO, HAGALAZ, ALGIZ | U16: 4 | V16: AESCULAPUS, AMATERASU, AMBERELLA, ARTEMIS, ASTARTE, BALDOR, BONA DEA, BRIGID, CUPRA, DIANA, DIONYSUS, FLIDAIS, HECATE, HYGIA, ISIS, JUTERNA, KWAI-YIN, KWAN-YIN AND BUDDHA, LUNA, MARS | W16: 28 | X16: Hold | Y16: Hold | Z16: Spell Jar | AA16: Yes | AB16: Maybe | AC16: Yes | AD16: Hold boundaries, guard, ward and keep protection steady. | AE16: App should pull this row's Greenman Energy Mode from the main item sheets. Use Secondary Energy Hint only if a serious/adult spell still needs a Draw/Hold/Release/Open/Transform flavour. | AF16: Hang it in the home | AG16: Keep it hidden and safe | Bury in the earth
A17: Divination, Dreams & Psychic Work | B17: Clairvoyance | C17: Waxing/Full | D17: Air | E17: Mercury | F17: Wednesday | G17: Yellow | H17: East | I17: Projective | J17: Yellow, white, crimson | K17: 5 | L17: Communication, fulfilment | M17: 1 or 3 | N17: ANISE, BASIL, BAY LAUREL, CAMPHOR SYNTHETIC, CINNAMON STICKS, CLEAVERS, CLOVES, COLTSFOOT, GARLIC POWDER, GINGER ROOT, JUNIPER BERRIES, LAVENDER FLOWERS, LEMON BALM, NUTMEG POWDER, OAKBARK RED, OREGANO, PARSLEY, PEPPERMINT, ROSE BUDS RED, ROSEMARY, SAGE, SANDALWOOD RED, SANDALWOOD WHITE, SEA SALT, THYME | O17: 25 | P17: agate Blue Lace , agate Moss , Amazonite, Amethyst, Apache Tears, Aquamarine, Calcite, Carnelian, Quartz Clear , Emerald, Flourite, Fuchsite, Howlite, Iolite, Jet, Kyanite, Labradorite, Lapis Lazuli, Moonstone, obsidian snowflake, Opal pink, Peridot, Petrified Wood, quartz rutilated , Sapphire, Seraphinite, Serpentine, Sodalite, Sugilite, Sunstone, Tanzanite, Tiger Eye gold, Topaz, Turquoise, Yellow Aventurine | Q17: 35 | R17: Bergamot, Honeysuckle, Lavender, Neroli, Peppermint, Sandalwood In. | S17: 6 | T17: ANSUZ, PERTH, SOWILO, TIWAZ, LAGUZ, DAGAZ | U17: 6 | V17: ALL GODDESSES, ALL LUNAR GODDESSES, ARADIA, ARES, ARIANRHOD, BEFANA, CUPRA, DIANA, GOD AND GODDESS IN BALANCE, HECATE, KWAI-YIN, LOKI, LUNA, MOTHER GODESS, NUIT, RA, SELENE, SOL, SOPHIA, TITIANA | W17: 26 | X17: Open / Reveal | Y17: Open / Reveal | Z17: Smoke and Flame | AA17: Maybe | AB17: Yes | AC17: Yes | AD17: Open sight, smoke, dream roads and hidden knowledge. | AE17: App should pull this row's Greenman Energy Mode from the main item sheets. Use Secondary Energy Hint only if a serious/adult spell still needs a Draw/Hold/Release/Open/Transform flavour. | AF17: Carry it close on your person | AG17: Place at a shrine or altar | Place in a tree
A18: Divination, Dreams & Psychic Work | B18: Divination | C18: Full | D18: Air | E18: Mercury | F18: Wednesday | G18: Yellow | H18: East | I18: Projective | J18: Yellow, white, crimson | K18: 5 | L18: Communication, fulfilment | M18: 1 or 3 | N18: ANISE, BASIL, BAY LAUREL, BLACK TEA, CINNAMON STICKS, CLOVES, COLTSFOOT, COMFREY, FENNEL (SEED), GARLIC POWDER, GOLDENROD, JASMINE, LAVENDER FLOWERS, NUTMEG POWDER, ORRIS ROOT POWDER, PARSLEY, PEPPERMINT, PINE NUT, ROSE BUDS PINK, ROSE BUDS RED, SAGE, SANDALWOOD WHITE, THYME, VIOLET LEAVES, VIOLET, YARROW | O18: 26 | P18: Emerald, Jet, Moonstone, obsidian snowflake, Onyx, Sapphire, Tanzanite | Q18: 7 | R18: Lemon Grass, Orange Bitter | S18: 2 | T18: ANSUZ, PERTH, LAGUZ | U18: 3 | V18: ALL GODDESSES, ALL LUNAR GODDESSES, ARADIA, ARES, ARIANRHOD, BEFANA, CUPRA, DIANA, GOD AND GODDESS IN BALANCE, HECATE, KWAI-YIN, LUNA, MOTHER GODESS, NUIT, RA, SELENE, SOL, SOPHIA, TITIANA, VAC | W18: 28 | X18: Open / Reveal | Y18: Open / Reveal | Z18: Smoke and Flame | AA18: Maybe | AB18: Yes | AC18: Yes | AD18: Open sight, smoke, dream roads and hidden knowledge. | AE18: App should pull this row's Greenman Energy Mode from the main item sheets. Use Secondary Energy Hint only if a serious/adult spell still needs a Draw/Hold/Release/Open/Transform flavour. | AF18: Place at a shrine or altar | AG18: Carry it close on your person | Place in a tree
A19: Divination, Dreams & Psychic Work | B19: Prophetic dreams | C19: Full | D19: Water | E19: Moon | F19: Monday | G19: Blue | H19: West | I19: Receptive | J19: Blue, turquoise, green, grey, indigo, black | K19: 2 | L19: Duality, balance, couples, partnerships | M19: 1 or 3 | N19: BASIL, BAY LAUREL, CAMPHOR SYNTHETIC, CARAWAY, COLTSFOOT, EYEBRIGHT, GOLDENROD, JASMINE, LAVENDER FLOWERS, LEMON VERBENA, MARIGOLD, MULLEIN, NUTMEG POWDER, OAKBARK RED, ORRIS ROOT POWDER, PEPPERMINT, ROSE BUDS RED, ROSE PETALS, ROSEMARY, THYME, VIOLET LEAVES, VIOLET | O19: 22 | P19: Amethyst, Opal pink, Peridot, Pyrite (Fool's Gold), Sugilite | Q19: 5 | R19: Lavender, Sandalwood In., Juniper, Melissa | S19: 4 | T19: ANSUZ, PERTH, SOWILO, MANNAZ | U19: 4 | V19: ALL GODDESSES, ALL LUNAR GODDESSES, ARADIA, ARES, ARIANRHOD, BEFANA, CUPRA, DIANA, GOD AND GODDESS IN BALANCE, HECATE, JUTERNA, KWAI-YIN, LUNA, MOTHER GODESS, NUIT, RA, SELENE, SOL, SOPHIA, TITIANA | W19: 25 | X19: Open / Reveal | Y19: Open / Reveal | Z19: Smoke and Flame | AA19: Maybe | AB19: Yes | AC19: Yes | AD19: Open sight, smoke, dream roads and hidden knowledge. | AE19: App should pull this row's Greenman Energy Mode from the main item sheets. Use Secondary Energy Hint only if a serious/adult spell still needs a Draw/Hold/Release/Open/Transform flavour. | AF19: Keep it hidden and safe | AG19: Place at a shrine or altar | Carry it close on your person
A20: Divination, Dreams & Psychic Work | B20: Negating dreams | C20: Waning | D20: Water | E20: Moon | F20: Monday | G20: Blue | H20: West | I20: Receptive | J20: Blue, turquoise, green, grey, indigo, black | K20: 2 | L20: Duality, balance, couples, partnerships | M20: 1 or 3 | N20: ANISE, CHAMOMILE, DILL, GARLIC POWDER, JASMINE, LAVENDER FLOWERS, MULLEIN, OAKBARK RED, PEPPERMINT, ROSEMARY, THYME, VALERIAN ROOT | O20: 12 | P20: Lepidolite, Red Jasper, Ruby | Q20: 3 | R20: Cedarwood | S20: 1 | T20: LAGUZ | U20: 1 | V20: SELENE, LUNA, HECATE, DIANA, ODIN, SATURN, MERCURY | W20: 7 | X20: Release | Y20: Release | Z20: Smoke and Flame | AA20: Maybe | AB20: Yes | AC20: Yes | AD20: Open sight, smoke, dream roads and hidden knowledge. | AE20: App should pull this row's Greenman Energy Mode from the main item sheets. Use Secondary Energy Hint only if a serious/adult spell still needs a Draw/Hold/Release/Open/Transform flavour. | AF20: Bury in the earth | AG20: Leave in running water | Burn and release, no remains
A21: Divination, Dreams & Psychic Work | B21: Subconscious work | C21: Dark | D21: Water | E21: Moon | F21: Monday | G21: Black | H21: West | I21: Receptive | J21: Blue, turquoise, green, grey, indigo, black | K21: 2 | L21: Duality, balance, couples, partnerships | M21: 1 or 3 | N21: BASIL, BAY LAUREL, CAMPHOR SYNTHETIC, CARAWAY, COLTSFOOT, EYEBRIGHT, GOLDENROD, JASMINE, LAVENDER FLOWERS, LEMON VERBENA, MARIGOLD, MULLEIN, NUTMEG POWDER, OAKBARK RED, ORRIS ROOT POWDER, PEPPERMINT, ROSE BUDS RED, ROSE PETALS, ROSEMARY, THYME, VIOLET LEAVES, VIOLET | O21: 22 | P21: Amethyst, Opal pink, Peridot, Pyrite (Fool's Gold), Sugilite | Q21: 5 | R21: Sandalwood In., Frankincense, Lavender, Patchouli | S21: 4 | T21: ANSUZ, PERTH, SOWILO, MANNAZ | U21: 4 | V21: ALL GODDESSES, ALL LUNAR GODDESSES, ARADIA, ARES, ARIANRHOD, BEFANA, CUPRA, DIANA, GOD AND GODDESS IN BALANCE, HECATE, JUTERNA, KWAI-YIN, LUNA, MOTHER GODESS, NUIT, RA, SELENE, SOL, SOPHIA, TITIANA | W21: 25 | X21: Open / Reveal | Y21: Open / Reveal | Z21: Smoke and Flame | AA21: Maybe | AB21: Yes | AC21: Yes | AD21: Open sight, smoke, dream roads and hidden knowledge. | AE21: App should pull this row's Greenman Energy Mode from the main item sheets. Use Secondary Energy Hint only if a serious/adult spell still needs a Draw/Hold/Release/Open/Transform flavour. | AF21: Carry it close on your person | AG21: Place at a shrine or altar | Keep it hidden and safe
A22: Cleansing, Purification & Healing | B22: Cleansing | C22: Waning | D22: Water | E22: Moon | F22: Monday | G22: White | H22: West | I22: Receptive | J22: Blue, turquoise, green, grey, indigo, black | K22: 2 | L22: Duality, balance, couples, partnerships | M22: 1, 3 or 7 | N22: AGRIMONY, ANISE, BASIL, BAY LAUREL, CAMPHOR SYNTHETIC, CEDARWOOD (HIMALAYAN), CHIVE, CLOVER, CLOVER RED, CLOVES, COMFREY, DEVILS CLAW ROOT, DRAGON'S BLOOD, FRANKINCENSE, GARLIC POWDER, HOREHOUND, HYSSOP, JUNIPER BERRIES, LAVENDER FLOWERS, LEMON VERBENA, LEMONGRASS, MULLEIN, MUSTARD SEED WHITE, MYRRH GUM, OAKLEAF, PENNYROYAL, PEPPERMINT, PINE NUT, ROSE HIP, ROSEMARY, RUE, SAGE, SANDALWOOD RED, SANDALWOOD WHITE, SEA SALT, THYME, VALERIAN ROOT, VERVAIN, VIOLET, WITCH HAZEL LEAVES, BLACK SALT, WORMWOOD | O22: 42 | P22: Aquamarine, Hematite, Lepidolite, Obsidian, quartz smokey , quartz snow , Serpentine, Tourmalinee Black | Q22: 8 | R22: Fir Needle, Frankincense, Lemon Grass, Sandalwood w.i., Tea Tree, Ylang Ylang | S22: 6 | T22: THURISAZ, HAGALAZ, IHWAZ, ALGIZ, LAGUZ | U22: 5 | V22: AMBERELLA, ARTEMIS, BALDOR, CUPRA, DIANA, FLIDAIS, HECATE, HEL, HYGIA, ISIS, JUTERNA, KWAN-YIN AND BUDDHA, LUNA, MARS, SHIVA, THOR, ZEUS | W22: 17 | X22: Release | Y22: Release | Z22: Smoke and Flame | AA22: Maybe | AB22: Yes | AC22: Yes | AD22: Clear, cleanse, restore or soothe depending on chosen spell. | AE22: App should pull this row's Greenman Energy Mode from the main item sheets. Use Secondary Energy Hint only if a serious/adult spell still needs a Draw/Hold/Release/Open/Transform flavour. | AF22: Burn and release, no remains | AG22: Bury in the earth | Leave in running water
A23: Cleansing, Purification & Healing | B23: Dispelling sickness | C23: Waning | D23: Fire | E23: Sun | F23: Sunday | G23: Orange | H23: South | I23: Projective | J23: Red, gold, crimson, orange, white | K23: 1 | L23: Developing the self, the All, wholeness, unity, beginnings | M23: 1, 3 or 7 | N23: AGRIMONY, ANISE, BASIL, BAY LAUREL, CHIVE, CLOVES, COLTSFOOT, DILL, DRAGON'S BLOOD, ELDERFLOWER, FENNEL (SEED), GINGER ROOT, HOREHOUND, LAVENDER FLOWERS, LEMONGRASS, LINSEED, MULLEIN, MUSTARD SEED WHITE, MYRRH GUM, OAKLEAF, SWEET MYRRH, PENNYROYAL, PEPPERMINT, PINE NUT, ROSEMARY, RUE, SAGE, SANDALWOOD RED, TANSY, VERVAIN, BLACK SALT | O23: 31 | P23: Obsidian, obsidian snowflake, Tourmalinee Black , Turquoise, Amber | Q23: 5 | R23: Frankincense | S23: 1 | T23: THURISAZ, KAUNO, HAGALAZ, ALGIZ | U23: 4 | V23: AESCULAPUS, AMATERASU, AMBERELLA, ARTEMIS, ASTARTE, BALDOR, BONA DEA, BRIGID, CUPRA, DIANA, DIONYSUS, FLIDAIS, HECATE, HYGIA, ISIS, JUTERNA, KWAI-YIN, KWAN-YIN AND BUDDHA, LUNA, MARS | W23: 28 | X23: Release | Y23: Release | Z23: Smoke and Flame | AA23: Maybe | AB23: Yes | AC23: Yes | AD23: Clear, cleanse, restore or soothe depending on chosen spell. | AE23: App should pull this row's Greenman Energy Mode from the main item sheets. Use Secondary Energy Hint only if a serious/adult spell still needs a Draw/Hold/Release/Open/Transform flavour. | AF23: Burn and release, no remains | AG23: Bury in the earth
A24: Cleansing, Purification & Healing | B24: Healing | C24: Waxing | D24: Water | E24: Moon | F24: Monday | G24: Blue | H24: West | I24: Receptive | J24: Blue, turquoise, green, grey, indigo, black | K24: 2 | L24: Duality, balance, couples, partnerships | M24: 1, 3 or 7 | N24: AGRIMONY, BAY LAUREL, BLACK TEA, CALAMUS ROOT, CAMPHOR SYNTHETIC, CINNAMON STICKS, CLEAVERS, COLTSFOOT, COMFREY, GARLIC POWDER, GOLDENSEAL ROOT, HOREHOUND, LAVENDER FLOWERS, LEMON BALM, LINSEED, MUSTARD SEED WHITE, MYRRH GUM, OAKBARK RED, OAKLEAF, SWEET MYRRH, PENNYROYAL, PEPPERMINT, PINE NUT, ROSE BUDS PINK, ROSE BUDS RED, ROSE PETALS, ROSEMARY, RUE, SAGE, SANDALWOOD RED, SANDALWOOD WHITE, ST JOHN'S WORT, THYME, VIOLET LEAVES, VIOLET, WORMWOOD | O24: 36 | P24: agate Blue Lace , agate Botswana , agate Moss , Bloodstone, Calcite, Chrysocolla, Citrine, Quartz Clear , Fuchsite, Howlite, Jade (jadeite), Kyanite, Lepidolite, Lodestone, Peridot, quartz rutilated , quartz snow , Rhodocrosite, Rhodonite, Seraphinite, Yellow Aventurine | Q24: 21 | R24: Fir Needle, Geranium, Juniper, Marjoram, Melissa, Peppermint, Pine, Rosemary, Tea Tree, Thyme, Ginger, Sandalwood In. | S24: 12 | T24: URUZ, KAUNO, NAUDIZ, IHWAZ, SOWILO, BERKANAN, LAGUZ | U24: 7 | V24: AESCULAPUS, AMATERASU, AMBERELLA, ASTARTE, BONA DEA, BRIGID, DIONYSUS, FLIDAIS, GAIA, HECATE, HYGIA, ISIS, JUTERNA, KWAI-YIN, KWAN-YIN AND BUDDHA, MARY MAGDALENE, MINERVA, PLUTO, SECH, SEKHMET | W24: 21 | X24: Hold | Y24: Hold | Z24: Smoke and Flame | AA24: Maybe | AB24: Yes | AC24: Yes | AD24: Clear, cleanse, restore or soothe depending on chosen spell. | AE24: App should pull this row's Greenman Energy Mode from the main item sheets. Use Secondary Energy Hint only if a serious/adult spell still needs a Draw/Hold/Release/Open/Transform flavour. | AF24: Carry it close on your person | AG24: Place at a shrine or altar | Hang it in the home
A25: Cleansing, Purification & Healing | B25: Purification | C25: Waning | D25: Fire | E25: Sun | F25: Sunday | G25: White | H25: South | I25: Projective | J25: Red, gold, crimson, orange, white | K25: 1 | L25: Developing the self, the All, wholeness, unity, beginnings | M25: 1, 3 or 7 | N25: AGRIMONY, ANISE, BASIL, BAY LAUREL, BENZOIN, BLACKBERRY LEAVES, CAMPHOR SYNTHETIC, CARAWAY, CEDARWOOD (HIMALAYAN), CHAMOMILE, CHRYSANTHEMUM, CINNAMON STICKS, CLEAVERS, CLOVER RED, CLOVES, DEVILS CLAW ROOT, DRAGON'S BLOOD, FENNEL (SEED), GARLIC POWDER, HYSSOP, JUNIPER BERRIES, LADIES MANTLE, LAVENDER FLOWERS, MYRRH GUM, MYRRH GUM POWDER, OAKLEAF, SWEET MYRRH, PARSLEY, PENNYROYAL, PEPPERMINT, PINE NUT, ROSE BUDS RED, ROSE HIP, ROSEMARY, RUE, SAGE, SANDALWOOD WHITE, SEA SALT, THYME, TONKA BEANS, VALERIAN ROOT, WITCH HAZEL LEAVES, BLACK SALT | O25: 43 | P25: Aquamarine, Quartz Clear , quartz snow , Seraphinite | Q25: 4 | R25: Cedarwood, Clove Bud, Fir Needle, Lavender, Lemon, Neroli, Peppermint, Pine, Rosemary, Tea Tree, Thyme, Cinnamon, Sandalwood In. | S25: 13 | T25: THURISAZ, ISA, HAGALAZ, ALGIZ | U25: 4 | V25: GAIA, HYGIA, JUTERNA, BALDUR | W25: 4 | X25: Release | Y25: Release | Z25: Smoke and Flame | AA25: Maybe | AB25: Yes | AC25: Yes | AD25: Clear, cleanse, restore or soothe depending on chosen spell. | AE25: App should pull this row's Greenman Energy Mode from the main item sheets. Use Secondary Energy Hint only if a serious/adult spell still needs a Draw/Hold/Release/Open/Transform flavour. | AF25: Burn and release, no remains | AG25: Bury in the earth | Leave in running water
A26: Power, Strength & Confidence | B26: Bolstering spells | C26: Waxing | D26: Fire | E26: Sun | F26: Sunday | G26: Gold | H26: South | I26: Projective | J26: Red, gold, crimson, orange, white | K26: 1 | L26: Developing the self, the All, wholeness, unity, beginnings | M26: 1 or 3 | N26: CALAMUS ROOT, DRAGON'S BLOOD, DRAGON'S BLOOD RESIN, GARLIC POWDER, GOLDENSEAL ROOT, JUNIPER BERRIES, LADIES MANTLE, LAVENDER FLOWERS, SWEET MYRRH, ROSE BUDS PINK, WORMWOOD | O26: 11 | P26: Ametrine, Aragonite, Calcite, Quartz Clear , Flourite, Garnet, Hematite, Iolite, Labradorite, Lapis Lazuli, Malachite, quartz rutilated , Sapphire, Seraphinite, Serpentine, Sugilite, Tourmalinee Black | Q26: 17 | R26: Apple | S26: 1 | T26: URUZ, THURISAZ | U26: 2 | V26: LOKI, SOPHIA, VAC, VAK, ODIN, VERDANDI | W26: 6 | X26: Hold | Y26: Hold | Z26: Charm Bag | AA26: Maybe | AB26: Maybe | AC26: Yes | AD26: Carry courage, strength, focus or confidence close to the body. | AE26: App should pull this row's Greenman Energy Mode from the main item sheets. Use Secondary Energy Hint only if a serious/adult spell still needs a Draw/Hold/Release/Open/Transform flavour. | AF26: Carry it close on your person | AG26: Place at a shrine or altar
A27: Power, Strength & Confidence | B27: Confidence | C27: Waxing | D27: Fire | E27: Sun | F27: Sunday | G27: Gold | H27: South | I27: Projective | J27: Red, gold, crimson, orange, white | K27: 1 | L27: Developing the self, the All, wholeness, unity, beginnings | M27: 1 or 3 | N27: ACORN, BASIL, CALAMUS ROOT, DILL, FENNEL (SEED), GARLIC POWDER, OAKBARK RED, ROSEMARY, THYME | O27: 9 | P27: Aragonite, Bloodstone, Carnelian, Flourite, Goldstone, Kyanite, Malachite, Rhodonite, Ruby, Sunstone, Tiger Eye gold, Topaz, Unakite, Yellow Aventurine, Amber | Q27: 15 | R27: Bergamot, Neroli, Thyme | S27: 3 | T27: FEHU, URUZ, WUNJO, NAUDIZ, TIWAZ | U27: 5 | V27: ALL, ALL GODDESSES, ALL LUNAR GODDESSES, AMATERASU, AMBERELLA, APHRODITE, ARES, ASTARTE, BALDUR & HATHOR, BUDDHA, CUPID, CUPRA, CYBELE, KWAN-YIN AND BUDDHA, LATONA, MAAT, MARS, MINERVA, MOTHER GODDESS, PARVATI | W27: 30 | X27: Hold | Y27: Hold | Z27: Charm Bag | AA27: Maybe | AB27: Maybe | AC27: Yes | AD27: Carry courage, strength, focus or confidence close to the body. | AE27: App should pull this row's Greenman Energy Mode from the main item sheets. Use Secondary Energy Hint only if a serious/adult spell still needs a Draw/Hold/Release/Open/Transform flavour. | AF27: Carry it close on your person | AG27: Place where it can be seen
A28: Power, Strength & Confidence | B28: Magical power | C28: Waxing/Full | D28: Fire | E28: Sun | F28: Sunday | G28: Gold | H28: South | I28: Projective | J28: Red, gold, crimson, orange, white | K28: 1 | L28: Developing the self, the All, wholeness, unity, beginnings | M28: 1 or 3 | N28: CALAMUS ROOT, DRAGON'S BLOOD, DRAGON'S BLOOD RESIN, GARLIC POWDER, GOLDENSEAL ROOT, JUNIPER BERRIES, LADIES MANTLE, LAVENDER FLOWERS, SWEET MYRRH, ROSE BUDS PINK, WORMWOOD | O28: 11 | P28: Ametrine, Aragonite, Calcite, Quartz Clear , Flourite, Garnet, Hematite, Iolite, Labradorite, Lapis Lazuli, Malachite, quartz rutilated , Sapphire, Seraphinite, Serpentine, Sugilite, Tourmalinee Black | Q28: 17 | R28: Apple | S28: 1 | T28: URUZ, THURISAZ | U28: 2 | V28: LOKI, SOPHIA, VAC, VAK, ODIN, VERDANDI | W28: 6 | X28: Hold | Y28: Hold | Z28: Charm Bag | AA28: Maybe | AB28: Maybe | AC28: Yes | AD28: Carry courage, strength, focus or confidence close to the body. | AE28: App should pull this row's Greenman Energy Mode from the main item sheets. Use Secondary Energy Hint only if a serious/adult spell still needs a Draw/Hold/Release/Open/Transform flavour. | AF28: Carry it close on your person | AG28: Place at a shrine or altar
A29: Power, Strength & Confidence | B29: Strength | C29: Waxing | D29: Fire | E29: Mars | F29: Tuesday | G29: Red | H29: South | I29: Projective | J29: Red, gold, crimson, orange, white | K29: 9 | L29: Aggression, conflict, dominance | M29: 1 or 3 | N29: ACORN, BASIL, BLACK TEA, FENNEL (SEED), GARLIC POWDER, MUSTARD SEED WHITE, OAKBARK RED, PINE NUT, ROSEMARY | O29: 9 | P29: agate Blue Lace , agate Botswana , agate Moss , Amazonite, Ametrine, Aragonite, Bloodstone, Carnelian, Chrysocolla, Citrine, Garnet, Goldstone, Hematite, Iolite, Labradorite, Lodestone, Obsidian, Onyx, Petrified Wood, quartz rutilated , quartz smokey , Ruby, Sodalite, Sunstone, Topaz | Q29: 25 | R29: Pine, Tea Tree, Ginger | S29: 3 | T29: URUZ, THURISAZ, HAGALAZ, NAUDIZ, IHWAZ, ALGIZ, TIWAZ | U29: 7 | V29: ALL, ALL GODDESSES, ALL LUNAR GODDESSES, AMATERASU, AMBERELLA, APHRODITE, ARES, ASTARTE, BALDUR & HATHOR, BUDDHA, CUPID, CUPRA, CYBELE, GAIA, HYGIA, KWAN-YIN AND BUDDHA, LATONA, MAAT, MARS, MINERVA | W29: 36 | X29: Hold | Y29: Hold | Z29: Charm Bag | AA29: Maybe | AB29: Maybe | AC29: Yes | AD29: Carry courage, strength, focus or confidence close to the body. | AE29: App should pull this row's Greenman Energy Mode from the main item sheets. Use Secondary Energy Hint only if a serious/adult spell still needs a Draw/Hold/Release/Open/Transform flavour. | AF29: Carry it close on your person | AG29: Place at a shrine or altar
A30: Power, Strength & Confidence | B30: Truth | C30: Waxing/Dark | D30: Air | E30: Mercury | F30: Wednesday | G30: Yellow | H30: East | I30: Projective | J30: Yellow, white, crimson | K30: 5 | L30: Communication, fulfilment | M30: 1 or 3 | N30: BASIL, BAY LAUREL, CAMPHOR SYNTHETIC, CARAWAY, COLTSFOOT, EYEBRIGHT, GOLDENROD, JASMINE, LAVENDER FLOWERS, LEMON VERBENA, MARIGOLD, MULLEIN, NUTMEG POWDER, OAKBARK RED, ORRIS ROOT POWDER, PEPPERMINT, ROSE BUDS RED, ROSE PETALS, ROSEMARY, THYME, VIOLET LEAVES, VIOLET | O30: 22 | P30: Amethyst, Opal pink, Peridot, Pyrite (Fool's Gold), Sugilite | Q30: 5 | R30: Frankincense, Bergamot, Peppermint, Rosemary | S30: 4 | T30: ANSUZ, PERTH, SOWILO, MANNAZ | U30: 4 | V30: ALL GODDESSES, ALL LUNAR GODDESSES, ARADIA, ARES, ARIANRHOD, BEFANA, CUPRA, DIANA, GOD AND GODDESS IN BALANCE, HECATE, JUTERNA, KWAI-YIN, LUNA, MOTHER GODESS, NUIT, RA, SELENE, SOL, SOPHIA, TITIANA | W30: 25 | X30: Open / Reveal | Y30: Open / Reveal | Z30: Charm Bag | AA30: Maybe | AB30: Maybe | AC30: Yes | AD30: Carry courage, strength, focus or confidence close to the body. | AE30: App should pull this row's Greenman Energy Mode from the main item sheets. Use Secondary Energy Hint only if a serious/adult spell still needs a Draw/Hold/Release/Open/Transform flavour. | AF30: Carry it close on your person | AG30: Place at a shrine or altar
